Workbook
Name SMS: Names!#REF!

Sheet Vendor Entry Sheet
A2: Date | B2: Name | C2: SAP ID | D2: Service Master Number | E2: Work Order Number | F2: Activity Number | G2: Work Center | H2: Work Hours | I2: Purchase Order Number | J2: Purchase Order Item Number
A3: Date in Format DD.MM.YYYY | B3: Employee Name | C3: Employee SAP ID | D3: Service Master Number | E3: Work Order Number | F3: Operation Number | G3: Main/ Operational Work Center | H3: Work Hours | I3: Purchase Order Number | J3: Purchase Order Item Number | K3: Role
C5: =IFERROR(VLOOKUP(B5,Names!$B$1:$E$253,2,FALSE),"") | D5: =IFERROR(VLOOKUP(B5,Names!$B$1:$E$253,4,FALSE),"") | I5: =IF(B5="","",Names!$G$21) | J5: =IF(B5="","",Names!$H$21) | K5: =IFERROR(VLOOKUP(B5,Names!$B$1:$E$253,3,FALSE),"")
C6: =IFERROR(VLOOKUP(B6,Names!$B$1:$E$253,2,FALSE),"") | D6: =IFERROR(VLOOKUP(B6,Names!$B$1:$E$253,4,FALSE),"") | I6: =IF(B6="","",Names!$G$21) | J6: =IF(B6="","",Names!$H$21) | K6: =IFERROR(VLOOKUP(B6,Names!$B$1:$E$253,3,FALSE),"")
C7: =IFERROR(VLOOKUP(B7,Names!$B$1:$E$253,2,FALSE),"") | D7: =IFERROR(VLOOKUP(B7,Names!$B$1:$E$253,4,FALSE),"") | I7: =IF(B7="","",Names!$G$21) | J7: =IF(B7="","",Names!$H$21) | K7: =IFERROR(VLOOKUP(B7,Names!$B$1:$E$253,3,FALSE),"")
C8: =IFERROR(VLOOKUP(B8,Names!$B$1:$E$253,2,FALSE),"") | D8: =IFERROR(VLOOKUP(B8,Names!$B$1:$E$253,4,FALSE),"") | I8: =IF(B8="","",Names!$G$21) | J8: =IF(B8="","",Names!$H$21) | K8: =IFERROR(VLOOKUP(B8,Names!$B$1:$E$253,3,FALSE),"")
C9: =IFERROR(VLOOKUP(B9,Names!$B$1:$E$253,2,FALSE),"") | D9: =IFERROR(VLOOKUP(B9,Names!$B$1:$E$253,4,FALSE),"") | I9: =IF(B9="","",Names!$G$21) | J9: =IF(B9="","",Names!$H$21) | K9: =IFERROR(VLOOKUP(B9,Names!$B$1:$E$253,3,FALSE),"")
C10: =IFERROR(VLOOKUP(B10,Names!$B$1:$E$253,2,FALSE),"") | D10: =IFERROR(VLOOKUP(B10,Names!$B$1:$E$253,4,FALSE),"") | I10: =IF(B10="","",Names!$G$21) | J10: =IF(B10="","",Names!$H$21) | K10: =IFERROR(VLOOKUP(B10,Names!$B$1:$E$253,3,FALSE),"")
C11: =IFERROR(VLOOKUP(B11,Names!$B$1:$E$253,2,FALSE),"") | D11: =IFERROR(VLOOKUP(B11,Names!$B$1:$E$253,4,FALSE),"") | I11: =IF(B11="","",Names!$G$21) | J11: =IF(B11="","",Names!$H$21) | K11: =IFERROR(VLOOKUP(B11,Names!$B$1:$E$253,3,FALSE),"")
C12: =IFERROR(VLOOKUP(B12,Names!$B$1:$E$253,2,FALSE),"") | D12: =IFERROR(VLOOKUP(B12,Names!$B$1:$E$253,4,FALSE),"") | I12: =IF(B12="","",Names!$G$21) | J12: =IF(B12="","",Names!$H$21) | K12: =IFERROR(VLOOKUP(B12,Names!$B$1:$E$253,3,FALSE),"")
C13: =IFERROR(VLOOKUP(B13,Names!$B$1:$E$253,2,FALSE),"") | D13: =IFERROR(VLOOKUP(B13,Names!$B$1:$E$253,4,FALSE),"") | I13: =IF(B13="","",Names!$G$21) | J13: =IF(B13="","",Names!$H$21) | K13: =IFERROR(VLOOKUP(B13,Names!$B$1:$E$253,3,FALSE),"")
C14: =IFERROR(VLOOKUP(B14,Names!$B$1:$E$253,2,FALSE),"") | D14: =IFERROR(VLOOKUP(B14,Names!$B$1:$E$253,4,FALSE),"") | I14: =IF(B14="","",Names!$G$21) | J14: =IF(B14="","",Names!$H$21) | K14: =IFERROR(VLOOKUP(B14,Names!$B$1:$E$253,3,FALSE),"")
C15: =IFERROR(VLOOKUP(B15,Names!$B$1:$E$253,2,FALSE),"") | D15: =IFERROR(VLOOKUP(B15,Names!$B$1:$E$253,4,FALSE),"") | I15: =IF(B15="","",Names!$G$21) | J15: =IF(B15="","",Names!$H$21) | K15: =IFERROR(VLOOKUP(B15,Names!$B$1:$E$253,3,FALSE),"")
C16: =IFERROR(VLOOKUP(B16,Names!$B$1:$E$253,2,FALSE),"") | D16: =IFERROR(VLOOKUP(B16,Names!$B$1:$E$253,4,FALSE),"") | I16: =IF(B16="","",Names!$G$21) | J16: =IF(B16="","",Names!$H$21) | K16: =IFERROR(VLOOKUP(B16,Names!$B$1:$E$253,3,FALSE),"")
... C110: =IFERROR(VLOOKUP(B110,Names!$B$1:$E$253,2,FALSE),"") | D110: =IFERROR(VLOOKUP(B110,Names!$B$1:$E$253,4,FALSE),"") | I110: =IF(B110="","",Names!$G$21) | J110: =IF(B110="","",Names!$H$21) | K110: =IFERROR(VLOOKUP(B110,Names!$B$1:$E$253,3,FALSE),"")
C111: =IFERROR(VLOOKUP(B111,Names!$B$1:$E$253,2,FALSE),"") | D111: =IFERROR(VLOOKUP(B111,Names!$B$1:$E$253,4,FALSE),"") | I111: =IF(B111="","",Names!$G$21) | J111: =IF(B111="","",Names!$H$21)
C112: =IFERROR(VLOOKUP(B112,Names!$B$1:$E$253,2,FALSE),"") | D112: =IFERROR(VLOOKUP(B112,Names!$B$1:$E$253,4,FALSE),"") | I112: =IF(B112="","",Names!$G$21) | J112: =IF(B112="","",Names!$H$21)
C113: =IFERROR(VLOOKUP(B113,Names!$B$1:$E$253,2,FALSE),"") | D113: =IFERROR(VLOOKUP(B113,Names!$B$1:$E$253,4,FALSE),"") | I113: =IF(B113="","",Names!$G$21) | J113: =IF(B113="","",Names!$H$21)
C114: =IFERROR(VLOOKUP(B114,Names!$B$1:$E$253,2,FALSE),"") | D114: =IFERROR(VLOOKUP(B114,Names!$B$1:$E$253,4,FALSE),"") | I114: =IF(B114="","",Names!$G$21) | J114: =IF(B114="","",Names!$H$21)
C115: =IFERROR(VLOOKUP(B115,Names!$B$1:$E$253,2,FALSE),"") | D115: =IFERROR(VLOOKUP(B115,Names!$B$1:$E$253,4,FALSE),"") | I115: =IF(B115="","",Names!$G$21) | J115: =IF(B115="","",Names!$H$21)
C116: =IFERROR(VLOOKUP(B116,Names!$B$1:$E$253,2,FALSE),"") | D116: =IFERROR(VLOOKUP(B116,Names!$B$1:$E$253,4,FALSE),"") | I116: =IF(B116="","",Names!$G$21) | J116: =IF(B116="","",Names!$H$21)
C117: =IFERROR(VLOOKUP(B117,Names!$B$1:$E$253,2,FALSE),"") | D117: =IFERROR(VLOOKUP(B117,Names!$B$1:$E$253,4,FALSE),"") | I117: =IF(B117="","",Names!$G$21) | J117: =IF(B117="","",Names!$H$21)
C118: =IFERROR(VLOOKUP(B118,Names!$B$1:$E$253,2,FALSE),"") | D118: =IFERROR(VLOOKUP(B118,Names!$B$1:$E$253,4,FALSE),"") | I118: =IF(B118="","",Names!$G$21) | J118: =IF(B118="","",Names!$H$21)
C119: =IFERROR(VLOOKUP(B119,Names!$B$1:$E$253,2,FALSE),"") | D119: =IFERROR(VLOOKUP(B119,Names!$B$1:$E$253,4,FALSE),"") | I119: =IF(B119="","",Names!$G$21) | J119: =IF(B119="","",Names!$H$21)
C120: =IFERROR(VLOOKUP(B120,Names!$B$1:$E$253,2,FALSE),"") | D120: =IFERROR(VLOOKUP(B120,Names!$B$1:$E$253,4,FALSE),"") | I120: =IF(B120="","",Names!$G$21) | J120: =IF(B120="","",Names!$H$21)
C121: =IFERROR(VLOOKUP(B121,Names!$B$1:$E$253,2,FALSE),"") | D121: =IFERROR(VLOOKUP(B121,Names!$B$1:$E$253,4,FALSE),"") | I121: =IF(B121="","",Names!$G$21) | J121: =IF(B121="","",Names!$H$21)
C122: =IFERROR(VLOOKUP(B122,Names!$B$1:$E$253,2,FALSE),"") | D122: =IFERROR(VLOOKUP(B122,Names!$B$1:$E$253,4,FALSE),"") | I122: =IF(B122="","",Names!$G$21) | J122: =IF(B122="","",Names!$H$21)
... C136: =IFERROR(VLOOKUP(B136,Names!$B$1:$E$253,2,FALSE),"") | D136: =IFERROR(VLOOKUP(B136,Names!$B$1:$E$253,4,FALSE),"") | I136: =IF(B136="","",Names!$G$21) | J136: =IF(B136="","",Names!$H$21)

Sheet Bulk Upload Tool (NML USE ONLY)
A1: Work date DD.MM.YYY | B1: Employee number | C1: Sending purchase order | D1: Sending purchase order item | E1: Activity Number Service Master | F1: Receiver Order - WO or Stat Order | G1: Network number | H1: Activity Number - Operation | I1: Work center | J1: WBS Element | K1: Plant | L1: Hours | M1: Unit of Measure | N1: Vendor Account Number - HR data | O1: Sending purchase order - HR data | P1: Sending purchase order item - HR data | Q1: Activity Number - HR data | R1: Activity Type - HR data | S1: Status | T1: Message
A2: ='Vendor Entry Sheet'!A4 -> 0 | B2: ='Vendor Entry Sheet'!C4 -> 0 | C2: ='Vendor Entry Sheet'!I4 -> 0 | D2: ='Vendor Entry Sheet'!J4 -> 0 | E2: ='Vendor Entry Sheet'!D4 -> 0 | F2: ='Vendor Entry Sheet'!E4 -> 0 | H2: ='Vendor Entry Sheet'!F4 -> 0 | I2: ='Vendor Entry Sheet'!G4 -> 0 | K2: 1005 | L2: ='Vendor Entry Sheet'!H4 -> 0 | M2: HR
A3: ='Vendor Entry Sheet'!A5 -> 0 | B3: ='Vendor Entry Sheet'!C5 | C3: ='Vendor Entry Sheet'!I5 | D3: ='Vendor Entry Sheet'!J5 | E3: ='Vendor Entry Sheet'!D5 | F3: ='Vendor Entry Sheet'!E5 -> 0 | H3: ='Vendor Entry Sheet'!F5 -> 0 | I3: ='Vendor Entry Sheet'!G5 -> 0 | K3: 1005 | L3: ='Vendor Entry Sheet'!H5 -> 0 | M3: HR
A4: ='Vendor Entry Sheet'!A6 -> 0 | B4: ='Vendor Entry Sheet'!C6 | C4: ='Vendor Entry Sheet'!I6 | D4: ='Vendor Entry Sheet'!J6 | E4: ='Vendor Entry Sheet'!D6 | F4: ='Vendor Entry Sheet'!E6 -> 0 | H4: ='Vendor Entry Sheet'!F6 -> 0 | I4: ='Vendor Entry Sheet'!G6 -> 0 | K4: 1005 | L4: ='Vendor Entry Sheet'!H6 -> 0 | M4: HR
A5: ='Vendor Entry Sheet'!A7 -> 0 | B5: ='Vendor Entry Sheet'!C7 | C5: ='Vendor Entry Sheet'!I7 | D5: ='Vendor Entry Sheet'!J7 | E5: ='Vendor Entry Sheet'!D7 | F5: ='Vendor Entry Sheet'!E7 -> 0 | H5: ='Vendor Entry Sheet'!F7 -> 0 | I5: ='Vendor Entry Sheet'!G7 -> 0 | K5: 1005 | L5: ='Vendor Entry Sheet'!H7 -> 0 | M5: HR
A6: ='Vendor Entry Sheet'!A8 -> 0 | B6: ='Vendor Entry Sheet'!C8 | C6: ='Vendor Entry Sheet'!I8 | D6: ='Vendor Entry Sheet'!J8 | E6: ='Vendor Entry Sheet'!D8 | F6: ='Vendor Entry Sheet'!E8 -> 0 | H6: ='Vendor Entry Sheet'!F8 -> 0 | I6: ='Vendor Entry Sheet'!G8 -> 0 | K6: 1005 | L6: ='Vendor Entry Sheet'!H8 -> 0 | M6: HR
A7: ='Vendor Entry Sheet'!A9 -> 0 | B7: ='Vendor Entry Sheet'!C9 | C7: ='Vendor Entry Sheet'!I9 | D7: ='Vendor Entry Sheet'!J9 | E7: ='Vendor Entry Sheet'!D9 | F7: ='Vendor Entry Sheet'!E9 -> 0 | H7: ='Vendor Entry Sheet'!F9 -> 0 | I7: ='Vendor Entry Sheet'!G9 -> 0 | K7: 1005 | L7: ='Vendor Entry Sheet'!H9 -> 0 | M7: HR
A8: ='Vendor Entry Sheet'!A10 -> 0 | B8: ='Vendor Entry Sheet'!C10 | C8: ='Vendor Entry Sheet'!I10 | D8: ='Vendor Entry Sheet'!J10 | E8: ='Vendor Entry Sheet'!D10 | F8: ='Vendor Entry Sheet'!E10 -> 0 | H8: ='Vendor Entry Sheet'!F10 -> 0 | I8: ='Vendor Entry Sheet'!G10 -> 0 | K8: 1005 | L8: ='Vendor Entry Sheet'!H10 -> 0 | M8: HR
A9: ='Vendor Entry Sheet'!A11 -> 0 | B9: ='Vendor Entry Sheet'!C11 | C9: ='Vendor Entry Sheet'!I11 | D9: ='Vendor Entry Sheet'!J11 | E9: ='Vendor Entry Sheet'!D11 | F9: ='Vendor Entry Sheet'!E11 -> 0 | H9: ='Vendor Entry Sheet'!F11 -> 0 | I9: ='Vendor Entry Sheet'!G11 -> 0 | K9: 1005 | L9: ='Vendor Entry Sheet'!H11 -> 0 | M9: HR
A10: ='Vendor Entry Sheet'!A12 -> 0 | B10: ='Vendor Entry Sheet'!C12 | C10: ='Vendor Entry Sheet'!I12 | D10: ='Vendor Entry Sheet'!J12 | E10: ='Vendor Entry Sheet'!D12 | F10: ='Vendor Entry Sheet'!E12 -> 0 | H10: ='Vendor Entry Sheet'!F12 -> 0 | I10: ='Vendor Entry Sheet'!G12 -> 0 | K10: 1005 | L10: ='Vendor Entry Sheet'!H12 -> 0 | M10: HR
A11: ='Vendor Entry Sheet'!A13 -> 0 | B11: ='Vendor Entry Sheet'!C13 | C11: ='Vendor Entry Sheet'!I13 | D11: ='Vendor Entry Sheet'!J13 | E11: ='Vendor Entry Sheet'!D13 | F11: ='Vendor Entry Sheet'!E13 -> 0 | H11: ='Vendor Entry Sheet'!F13 -> 0 | I11: ='Vendor Entry Sheet'!G13 -> 0 | K11: 1005 | L11: ='Vendor Entry Sheet'!H13 -> 0 | M11: HR
A12: ='Vendor Entry Sheet'!A14 -> 0 | B12: ='Vendor Entry Sheet'!C14 | C12: ='Vendor Entry Sheet'!I14 | D12: ='Vendor Entry Sheet'!J14 | E12: ='Vendor Entry Sheet'!D14 | F12: ='Vendor Entry Sheet'!E14 -> 0 | H12: ='Vendor Entry Sheet'!F14 -> 0 | I12: ='Vendor Entry Sheet'!G14 -> 0 | K12: 1005 | L12: ='Vendor Entry Sheet'!H14 -> 0 | M12: HR
A13: ='Vendor Entry Sheet'!A15 -> 0 | B13: ='Vendor Entry Sheet'!C15 | C13: ='Vendor Entry Sheet'!I15 | D13: ='Vendor Entry Sheet'!J15 | E13: ='Vendor Entry Sheet'!D15 | F13: ='Vendor Entry Sheet'!E15 -> 0 | H13: ='Vendor Entry Sheet'!F15 -> 0 | I13: ='Vendor Entry Sheet'!G15 -> 0 | K13: 1005 | L13: ='Vendor Entry Sheet'!H15 -> 0 | M13: HR
... A339: ='Vendor Entry Sheet'!A341 -> 0 | B339: ='Vendor Entry Sheet'!C341 -> 0 | C339: ='Vendor Entry Sheet'!I341 -> 0 | D339: ='Vendor Entry Sheet'!J341 -> 0 | E339: ='Vendor Entry Sheet'!D341 -> 0 | F339: ='Vendor Entry Sheet'!E341 -> 0 | H339: ='Vendor Entry Sheet'!F341 -> 0 | I339: ='Vendor Entry Sheet'!G341 -> 0 | K339: 1005 | L339: ='Vendor Entry Sheet'!H341 -> 0 | M339: HR

Sheet Approval Box (OFFICE ONLY)

Sheet Names
A1: Company | B1: Name | C1: Sap ID | D1: Role | E1: Service Master | G1: Role | H1: Service Master | J1: Company | K1: Purchase order | L1: Item number
A2: Boom | B2: Jarod Braithwaite | C2: 90140920 | D2: Boom Supervisor | E2: 3001951 | G2: Crane Operator | H2: 3001951 | J2: TMS | K2: 4700020660 | L2: 10
A3: Boom | B3: Michael Bird | C3: 90301465 | D3: Crane Operator | E3: 3001951 | G3: Boom Rigger | H3: 3001951 | J3: Boom | K3: 4700020658 | L3: 10
G4: Boom Supervisor | H4: 3001951 | J4: GMRS | K4: 4700020659 | L4: 10
A5: Boom | B5: Nicolo Montis | C5: 90300849 | D5: Boom Rigger | E5: 3001951 | G5: TMS Supervisor | H5: 3001951 | J5: Kings | K5: 4700020804 | L5: 10
A6: Boom | B6: Alhassan Koromah | C6: 90302562 | D6: Boom Rigger | E6: 3001951 | G6: TMS Boilermaker | H6: 3001951 | J6: Minprovise | K6: 4700020661 | L6: 10
A7: Boom | B7: Andre Bucci | C7: 90302563 | D7: Crane Operator | E7: 3001951 | G7: TMS Fitter | H7: 3001951 | J7: SMS Group | K7: 4700020657 | L7: 10
A8: Boom | B8: Aidan Taylor | C8: 90300016 | D8: Boom Rigger | E8: 3001951 | G8: GMRS Boilermaker | H8: 3001951
A9: Boom | B9: Egidio De Freitas | C9: 90301850 | D9: Crane Operator | E9: 3001951 | G9: GMRS Fitter | H9: 3001951
A10: Boom | B10: Madeleine Davidson | C10: 90302512 | D10: Boom Rigger | E10: 3001951 | G10: GMRS Supervisor | H10: 3001951
A11: Boom | B11: Mark Gibbons | C11: 90137237 | D11: Boom Supervisor | E11: 3001951 | G11: Kings Boilermaker | H11: 3001951
A12: Boom | B12: Tanirau Paki | C12: 90300199 | D12: Crane Operator | E12: 3001951 | G12: Kings Trade Assistant | H12: 3001951
A13: Boom | B13: Marvin Samuels | C13: 90300019 | D13: Boom Rigger | E13: 3001951 | G13: Kings Supervisor | H13: 3001951
A14: Boom | B14: Ashley Keatch | C14: 90301314 | D14: Boom Rigger | E14: 3001951 | G14: Minprovise Supervisor | H14: 3001951
A15: Boom | B15: Maruariki Lucky | C15: 90302329 | D15: Crane Operator | E15: 3001951 | G15: Minprovise Fitter | H15: 3001951
A16: Boom | B16: Joseph Kemp | C16: 90300213 | D16: Boom Rigger | E16: 3001951 | G16: Minprovise Boilermaker | H16: 3001951
A17: Boom | B17: Graeme Bozanich | C17: 90301259 | D17: Crane Operator | E17: 3001951 | G17: Minprovise Rigger | H17: 3001951
A18: Boom | B18: Hussein Mahumed | C18: 90300214 | D18: Boom Rigger | E18: 3001951 | G18: SMS Scaffolder | H18: 3001951
A19: GMRS | B19: Isaac Cheyne | C19: 90300498 | D19: GMRS Supervisor | E19: 3001951 | G19: SMS Sentry/ Gas tester | H19: 3001951
A20: GMRS | B20: Owen Finney | C20: 90302549 | D20: GMRS Fitter | E20: 3001951 | G20: SMS Supervisor | H20: 3001951
A21: GMRS | B21: Bryan Andal | C21: 90302546 | D21: GMRS Fitter | E21: 3001951
A22: GMRS | B22: Edward Santhanam | C22: 90300003 | D22: GMRS Boilermaker | E22: 3001951
A23: GMRS | B23: Jefferson Valcueba | C23: 90302529 | D23: GMRS Boilermaker | E23: 3001951
A24: GMRS | B24: Neale Edwards | C24: 90300039 | D24: GMRS Supervisor | E24: 3001951
A25: GMRS | B25: Dario Lopez | C25: 90144128 | D25: GMRS Fitter | E25: 3001951
A26: GMRS | B26: Sherwin Grantoza | C26: 90302547 | D26: GMRS Fitter | E26: 3001951
A27: GMRS | B27: Liam Brake | C27: 90301392 | D27: GMRS Boilermaker | E27: 3001951
A28: GMRS | B28: Liam McPhee | C28: 90302551 | D28: GMRS Boilermaker | E28: 3001951
A29: TMS | B29: Dean Naisbitt | C29: 90053092 | D29: TMS Supervisor | E29: 3001951
A30: TMS | B30: James Kilby | C30: 90300606 | D30: TMS Fitter | E30: 3001951
A31: TMS | B31: Abdelhikm Medellel | C31: 90302553 | D31: TMS Fitter | E31: 3001951
A32: TMS | B32: Amormio Chavez | C32: 90300753 | D32: TMS Boilermaker | E32: 3001951
... A47: Minprovise | B47: Erwan Merikhi | C47: 90302565 | D47: Minprovise Fitter | E47: 3001951
A48: Minprovise | E48: 3001951
A49: Minprovise | B49: Josh Colk | C49: 90137959 | D49: Minprovise Rigger | E49: 3001951
A50: Minprovise | B50: Paul Taylor | C50: 90117360 | D50: Supervisor | E50: 3001951
A51: Minprovise | B51: Joshua Galloway Mills | C51: 90302118 | D51: Minprovise Fitter | E51: 3001951
A52: Minprovise | B52: John Dinopol | C52: 90144804 | D52: Minprovise Boilermaker | E52: 3001951
A53: Minprovise | B53: Jericho Counsel | C53: 90302398 | D53: Minprovise Rigger | E53: 3001951
A54: Minprovise | B54: Lewid Davies | C54: 90302559 | D54: Minprovise Fitter | E54: 3001951
...

Sheet Work Orders
A1: Work Order | B1: Operation Number | C1: Work Order Header | D1: Op. Short Text | E1: Main Work Center | F1: Company
A2: 15215577 | B2: 0010 | C2: T1 ST001 HPP INSTRUMETS JB ELEC REDLINE | D2: ST001 HPP INSTRUMETS JB ELEC REDLINE | E2: TESUEL
A3: 15835660 | B3: 0005 | C3: T1 312CV003 Compressed Air Line Mech Rep | D3: 312CV003 Comp Air Line Mech Repl PREP | E3: 272SUME | F3: TMS
A4: 15835660 | B4: 0010 | C4: T1 312CV003 Compressed Air Line Mech Rep | D4: 312CV003 Comp Air Line Repl Scaff Instal | E4: 020SUSC | F4: SMS Group
A5: 15835660 | B5: 0020 | C5: T1 312CV003 Compressed Air Line Mech Rep | D5: 312CV003 Comp Air Line Mech Repl | E5: 272SUME | F5: TMS
A6: 15835660 | B6: 0030 | C6: T1 312CV003 Compressed Air Line Mech Rep | D6: 312CV003 Comp Air Line Repl 70T CN | E6: TCSWMC8
A7: 15835660 | B7: 0040 | C7: T1 312CV003 Compressed Air Line Mech Rep | D7: 312CV003 Comp Air Line Repl 70T CD | E7: 114SUCD | F7: Boom
A8: 15835660 | B8: 0050 | C8: T1 312CV003 Compressed Air Line Mech Rep | D8: 312CV003 Comp Air Line Repl 70T RG | E8: 114SURG | F8: Boom
A9: 15835660 | B9: 0060 | C9: T1 312CV003 Compressed Air Line Mech Rep | D9: 312CV003 Comp Air Line Repl Scaff Remove | E9: 020SUSC | F9: SMS Group
A10: 15967310 | B10: 0010 | C10: T1 ST001 Hydraulic Hose Tray Mech Repl | D10: ST001 Hydraulic Hose Tray Scaff Install | E10: 020SUSC | F10: SMS Group
A11: 15967310 | B11: 0020 | C11: T1 ST001 Hydraulic Hose Tray Mech Repl | D11: ST001 Hydraulic Hose Tray Mech Repl | E11: 272SUME | F11: TMS
A12: 15967310 | B12: 0030 | C12: T1 ST001 Hydraulic Hose Tray Mech Repl | D12: ST001 Hydraulic Hose Tray Scaff Remv | E12: 020SUSC | F12: SMS Group
A13: 16215807 | B13: 0010 | C13: T1 312CV003 MPV GTU Plough Adjust | D13: 312CV003 MPV GTU Plough Scaff Install | E13: 020SUSC | F13: SMS Group
A14: 16215807 | B14: 0020 | C14: T1 312CV003 MPV GTU Plough Adjust | D14: 312CV003 MPV GTU Plough Adjust Minprv FT | E14: 068SUME | F14: Minprovise
A15: 16215807 | B15: 0030 | C15: T1 312CV003 MPV GTU Plough Adjust | D15: 312CV003 MPV GTU Plough Adjust Minprv BM | E15: 068SUME | F15: Minprovise
A16: 16215807 | B16: 0040 | C16: T1 312CV003 MPV GTU Plough Adjust | D16: 312CV003 MPV GTU Plough Adjust Minprv TA | E16: 068SUME | F16: Minprovise
A17: 16215807 | B17: 0050 | C17: T1 312CV003 MPV GTU Plough Adjust | D17: 312CV003 MPV GTU Plough Scaff Remove | E17: 020SUSC | F17: SMS Group
A18: 16307398 | B18: 0010 | C18: T1 312CV002 Spray Bar Filter Ass MPV Ins | D18: T1 312CV002 Spray Bar Filter Ass MPV Ins | E18: 068SUBL | F18: Minprovise
A19: 16314597 | B19: 0010 | C19: T1 386BD004 Crush Contrl Rm Mech Scope | D19: 386BD004 TR1 Crush Contrl Rm Mech Scope | E19: TESUME
A20: 16314597 | B20: 0020 | C20: T1 386BD004 Crush Contrl Rm Mech Scope | D20: 386BD004 TR1 Crush Contrl Rm Elec Scope | E20: TESUEL
A21: 16314597 | B21: 0030 | C21: T1 386BD004 Crush Contrl Rm Mech Scope | E21: TEMSME
A22: 16314597 | B22: 0050 | C22: T1 386BD004 Crush Contrl Rm Mech Scope | E22: TEMSME
A23: 16314597 | B23: 0070 | C23: T1 386BD004 Crush Contrl Rm Mech Scope | E23: TEMSME
A24: 16314597 | B24: 0090 | C24: T1 386BD004 Crush Contrl Rm Mech Scope | E24: TEMSME
A25: 16314597 | B25: 0100 | C25: T1 386BD004 Crush Contrl Rm Mech Scope | E25: TEMSME
A26: 16317983 | B26: 0010 | C26: T1 312CV002 H&B Skirt Trial MPV Install | D26: T1 312CV002 H&B Skirt Trial MPV Install | E26: 068SUBL | F26: Minprovise
A27: 16317983 | B27: 0020 | C27: T1 312CV002 H&B Skirt Trial MPV Install | D27: T1 312CV002 H&B Skirt Trial BM Install | E27: 068SUBL | F27: Minprovise
A28: 16317983 | B28: 0030 | C28: T1 312CV002 H&B Skirt Trial MPV Install | D28: T1 312CV002 H&B Skirt Trial MPV Install | E28: 068SUBL | F28: Minprovise
A29: 16325968 | B29: 0010 | C29: T1 312CV002 Tail Guard Plough MPV Rpl | D29: 312CV002 Tail Guard Plough MPV Rpl | E29: 068SUME | F29: Minprovise
A30: 16325968 | B30: 0020 | C30: T1 312CV002 Tail Guard Plough MPV Rpl | D30: 312CV002 Tail Guard Plough MPV Rpl | E30: 068SUBL | F30: Minprovise
A31: 16330270 | B31: 0010 | C31: T1 312CV003 GTU Shedder Rubber MPV Repl | D31: T1 312CV003 GTU Erect Scaffold | E31: 020SUSC | F31: SMS Group
A32: 16330270 | B32: 0020 | C32: T1 312CV003 GTU Shedder Rubber MPV Repl | D32: T1 312CV003 GTU Shedder Rubber MPV Repl | E32: 068SUME | F32: Minprovise
A33: 16330270 | B33: 0030 | C33: T1 312CV003 GTU Shedder Rubber MPV Repl | D33: T1 312CV003 GTU WAH Spotter MPV | E33: 068SUME | F33: Minprovise
A34: 16330270 | B34: 0040 | C34: T1 312CV003 GTU Shedder Rubber MPV Repl | D34: T1 312CV003 GTU Erect Scaffold | E34: 020SUSC | F34: SMS Group
A35: 16330614 | B35: 0010 | C35: T1 312CV031 RH Remote Sensor HD Pulley R | D35: 312CV031 RH Remote Sensor HD Pulley Repl | E35: TESWCM
A36: 16330614 | B36: 0020 | C36: T1 312CV031 RH Remote Sensor HD Pulley R | D36: 312CV031 Replace RH Remote EWP | E36: TCSUEW01
A37: 16330614 | B37: 0030 | C37: T1 312CV031 RH Remote Sensor HD Pulley R | D37: 312CV031 Replace RH Remote Spotter | E37: 020SUST | F37: SMS Group
A38: 16333128 | B38: 0010 | C38: T1 Crusher Pressure TX Elec Inst | D38: Train 1 Crusher Balance pressure tx elec | E38: TESUEL
A39: 16338630 | B39: 0010 | C39: T1 312ST001 Turret Covers Mech Repl | D39: 312ST001 Slew Drive Covers Mech Replace | E39: TESUME
A40: 16338630 | B40: 0020 | C40: T1 312ST001 Turret Covers Mech Repl | D40: 312ST001 Slew Drive Covers Repl Sentry | E40: 020SUST | F40: SMS Group
...
