Workbook

Sheet Vendor Entry Sheet
A2: Date | B2: Name | C2: SAP ID | D2: Service Master Number | E2: Work Order Number | F2: Activity Number | G2: Work Center | H2: Work Hours | I2: Purchase Order Number | J2: Purchase Order Item Number
A3: Date in Format DD.MM.YYYY | B3: Employee Name | C3: Employee SAP ID | D3: Service Master Number | E3: Work Order Number | F3: Operation Number | G3: Main/ Operational Work Center | H3: Work Hours | I3: Purchase Order Number | J3: Purchase Order Item Number | K3: Role
C5: =IFERROR(VLOOKUP(B5,Names!$B$1:$C$186,2,FALSE),"") | D5: =IFERROR(VLOOKUP(B5,Names!$B$1:$C$186,4,FALSE),"") | I5: =IF(B5="","",Names!$G$21) | J5: =IF(B5="","",Names!$H$21) | K5: =IFERROR(VLOOKUP(B5,Names!$B$1:$C$186,3,FALSE),"")
C6: =IFERROR(VLOOKUP(B6,Names!$B$1:$C$186,2,FALSE),"") | D6: =IFERROR(VLOOKUP(B6,Names!$B$1:$C$186,4,FALSE),"") | I6: =IF(B6="","",Names!$G$21) | J6: =IF(B6="","",Names!$H$21) | K6: =IFERROR(VLOOKUP(B6,Names!$B$1:$C$186,3,FALSE),"")
C7: =IFERROR(VLOOKUP(B7,Names!$B$1:$C$186,2,FALSE),"") | D7: =IFERROR(VLOOKUP(B7,Names!$B$1:$C$186,4,FALSE),"") | I7: =IF(B7="","",Names!$G$21) | J7: =IF(B7="","",Names!$H$21) | K7: =IFERROR(VLOOKUP(B7,Names!$B$1:$C$186,3,FALSE),"")
C8: =IFERROR(VLOOKUP(B8,Names!$B$1:$C$186,2,FALSE),"") | D8: =IFERROR(VLOOKUP(B8,Names!$B$1:$C$186,4,FALSE),"") | I8: =IF(B8="","",Names!$G$21) | J8: =IF(B8="","",Names!$H$21) | K8: =IFERROR(VLOOKUP(B8,Names!$B$1:$C$186,3,FALSE),"")
C9: =IFERROR(VLOOKUP(B9,Names!$B$1:$C$186,2,FALSE),"") | D9: =IFERROR(VLOOKUP(B9,Names!$B$1:$C$186,4,FALSE),"") | I9: =IF(B9="","",Names!$G$21) | J9: =IF(B9="","",Names!$H$21) | K9: =IFERROR(VLOOKUP(B9,Names!$B$1:$C$186,3,FALSE),"")
C10: =IFERROR(VLOOKUP(B10,Names!$B$1:$C$186,2,FALSE),"") | D10: =IFERROR(VLOOKUP(B10,Names!$B$1:$C$186,4,FALSE),"") | I10: =IF(B10="","",Names!$G$21) | J10: =IF(B10="","",Names!$H$21) | K10: =IFERROR(VLOOKUP(B10,Names!$B$1:$C$186,3,FALSE),"")
C11: =IFERROR(VLOOKUP(B11,Names!$B$1:$C$186,2,FALSE),"") | D11: =IFERROR(VLOOKUP(B11,Names!$B$1:$C$186,4,FALSE),"") | I11: =IF(B11="","",Names!$G$21) | J11: =IF(B11="","",Names!$H$21) | K11: =IFERROR(VLOOKUP(B11,Names!$B$1:$C$186,3,FALSE),"")
C12: =IFERROR(VLOOKUP(B12,Names!$B$1:$C$186,2,FALSE),"") | D12: =IFERROR(VLOOKUP(B12,Names!$B$1:$C$186,4,FALSE),"") | I12: =IF(B12="","",Names!$G$21) | J12: =IF(B12="","",Names!$H$21) | K12: =IFERROR(VLOOKUP(B12,Names!$B$1:$C$186,3,FALSE),"")
C13: =IFERROR(VLOOKUP(B13,Names!$B$1:$C$186,2,FALSE),"") | D13: =IFERROR(VLOOKUP(B13,Names!$B$1:$C$186,4,FALSE),"") | I13: =IF(B13="","",Names!$G$21) | J13: =IF(B13="","",Names!$H$21) | K13: =IFERROR(VLOOKUP(B13,Names!$B$1:$C$186,3,FALSE),"")
C14: =IFERROR(VLOOKUP(B14,Names!$B$1:$C$186,2,FALSE),"") | D14: =IFERROR(VLOOKUP(B14,Names!$B$1:$C$186,4,FALSE),"") | I14: =IF(B14="","",Names!$G$21) | J14: =IF(B14="","",Names!$H$21) | K14: =IFERROR(VLOOKUP(B14,Names!$B$1:$C$186,3,FALSE),"")
C15: =IFERROR(VLOOKUP(B15,Names!$B$1:$C$186,2,FALSE),"") | D15: =IFERROR(VLOOKUP(B15,Names!$B$1:$C$186,4,FALSE),"") | I15: =IF(B15="","",Names!$G$21) | J15: =IF(B15="","",Names!$H$21) | K15: =IFERROR(VLOOKUP(B15,Names!$B$1:$C$186,3,FALSE),"")
C16: =IFERROR(VLOOKUP(B16,Names!$B$1:$C$186,2,FALSE),"") | D16: =IFERROR(VLOOKUP(B16,Names!$B$1:$C$186,4,FALSE),"") | I16: =IF(B16="","",Names!$G$21) | J16: =IF(B16="","",Names!$H$21) | K16: =IFERROR(VLOOKUP(B16,Names!$B$1:$C$186,3,FALSE),"")
... C110: =IFERROR(VLOOKUP(B110,Names!$B$1:$C$186,2,FALSE),"") | D110: =IFERROR(VLOOKUP(B110,Names!$B$1:$C$186,4,FALSE),"") | I110: =IF(B110="","",Names!$G$21) | J110: =IF(B110="","",Names!$H$21) | K110: =IFERROR(VLOOKUP(B110,Names!$B$1:$C$186,3,FALSE),"")
C111: =IFERROR(VLOOKUP(B111,Names!$B$1:$C$186,2,FALSE),"") | D111: =IFERROR(VLOOKUP(B111,Names!$B$1:$C$186,4,FALSE),"") | I111: =IF(B111="","",Names!$G$21) | J111: =IF(B111="","",Names!$H$21)
C112: =IFERROR(VLOOKUP(B112,Names!$B$1:$C$186,2,FALSE),"") | D112: =IFERROR(VLOOKUP(B112,Names!$B$1:$C$186,4,FALSE),"") | I112: =IF(B112="","",Names!$G$21) | J112: =IF(B112="","",Names!$H$21)
C113: =IFERROR(VLOOKUP(B113,Names!$B$1:$C$186,2,FALSE),"") | D113: =IFERROR(VLOOKUP(B113,Names!$B$1:$C$186,4,FALSE),"") | I113: =IF(B113="","",Names!$G$21) | J113: =IF(B113="","",Names!$H$21)
C114: =IFERROR(VLOOKUP(B114,Names!$B$1:$C$186,2,FALSE),"") | D114: =IFERROR(VLOOKUP(B114,Names!$B$1:$C$186,4,FALSE),"") | I114: =IF(B114="","",Names!$G$21) | J114: =IF(B114="","",Names!$H$21)
C115: =IFERROR(VLOOKUP(B115,Names!$B$1:$C$186,2,FALSE),"") | D115: =IFERROR(VLOOKUP(B115,Names!$B$1:$C$186,4,FALSE),"") | I115: =IF(B115="","",Names!$G$21) | J115: =IF(B115="","",Names!$H$21)
C116: =IFERROR(VLOOKUP(B116,Names!$B$1:$C$186,2,FALSE),"") | D116: =IFERROR(VLOOKUP(B116,Names!$B$1:$C$186,4,FALSE),"") | I116: =IF(B116="","",Names!$G$21) | J116: =IF(B116="","",Names!$H$21)
C117: =IFERROR(VLOOKUP(B117,Names!$B$1:$C$186,2,FALSE),"") | D117: =IFERROR(VLOOKUP(B117,Names!$B$1:$C$186,4,FALSE),"") | I117: =IF(B117="","",Names!$G$21) | J117: =IF(B117="","",Names!$H$21)
C118: =IFERROR(VLOOKUP(B118,Names!$B$1:$C$186,2,FALSE),"") | D118: =IFERROR(VLOOKUP(B118,Names!$B$1:$C$186,4,FALSE),"") | I118: =IF(B118="","",Names!$G$21) | J118: =IF(B118="","",Names!$H$21)
C119: =IFERROR(VLOOKUP(B119,Names!$B$1:$C$186,2,FALSE),"") | D119: =IFERROR(VLOOKUP(B119,Names!$B$1:$C$186,4,FALSE),"") | I119: =IF(B119="","",Names!$G$21) | J119: =IF(B119="","",Names!$H$21)
C120: =IFERROR(VLOOKUP(B120,Names!$B$1:$C$186,2,FALSE),"") | D120: =IFERROR(VLOOKUP(B120,Names!$B$1:$C$186,4,FALSE),"") | I120: =IF(B120="","",Names!$G$21) | J120: =IF(B120="","",Names!$H$21)
C121: =IFERROR(VLOOKUP(B121,Names!$B$1:$C$186,2,FALSE),"") | D121: =IFERROR(VLOOKUP(B121,Names!$B$1:$C$186,4,FALSE),"") | I121: =IF(B121="","",Names!$G$21) | J121: =IF(B121="","",Names!$H$21)
C122: =IFERROR(VLOOKUP(B122,Names!$B$1:$C$186,2,FALSE),"") | D122: =IFERROR(VLOOKUP(B122,Names!$B$1:$C$186,4,FALSE),"") | I122: =IF(B122="","",Names!$G$21) | J122: =IF(B122="","",Names!$H$21)
... C136: =IFERROR(VLOOKUP(B136,Names!$B$1:$C$186,2,FALSE),"") | D136: =IFERROR(VLOOKUP(B136,Names!$B$1:$C$186,4,FALSE),"") | I136: =IF(B136="","",Names!$G$21) | J136: =IF(B136="","",Names!$H$21)

Sheet Bulk Upload Tool (NML USE ONLY)
A1: Work date DD.MM.YYY | B1: Employee number | C1: Sending purchase order | D1: Sending purchase order item | E1: Activity Number Service Master | F1: Receiver Order - WO or Stat Order | G1: Network number | H1: Activity Number - Operation | I1: Work center | J1: WBS Element | K1: Plant | L1: Hours | M1: Unit of Measure | N1: Vendor Account Number - HR data | O1: Sending purchase order - HR data | P1: Sending purchase order item - HR data | Q1: Activity Number - HR data | R1: Activity Type - HR data | S1: Status | T1: Message
A2: ='Vendor Entry Sheet'!A4 -> 0 | B2: ='Vendor Entry Sheet'!C4 -> 0 | C2: ='Vendor Entry Sheet'!I4 -> 0 | D2: ='Vendor Entry Sheet'!J4 -> 0 | E2: ='Vendor Entry Sheet'!D4 -> 0 | F2: ='Vendor Entry Sheet'!E4 -> 0 | H2: ='Vendor Entry Sheet'!F4 -> 0 | I2: ='Vendor Entry Sheet'!G4 -> 0 | K2: 1005 | L2: ='Vendor Entry Sheet'!H4 -> 0 | M2: HR
A3: ='Vendor Entry Sheet'!A5 -> 0 | B3: ='Vendor Entry Sheet'!C5 | C3: ='Vendor Entry Sheet'!I5 | D3: ='Vendor Entry Sheet'!J5 | E3: ='Vendor Entry Sheet'!D5 | F3: ='Vendor Entry Sheet'!E5 -> 0 | H3: ='Vendor Entry Sheet'!F5 -> 0 | I3: ='Vendor Entry Sheet'!G5 -> 0 | K3: 1005 | L3: ='Vendor Entry Sheet'!H5 -> 0 | M3: HR
A4: ='Vendor Entry Sheet'!A6 -> 0 | B4: ='Vendor Entry Sheet'!C6 | C4: ='Vendor Entry Sheet'!I6 | D4: ='Vendor Entry Sheet'!J6 | E4: ='Vendor Entry Sheet'!D6 | F4: ='Vendor Entry Sheet'!E6 -> 0 | H4: ='Vendor Entry Sheet'!F6 -> 0 | I4: ='Vendor Entry Sheet'!G6 -> 0 | K4: 1005 | L4: ='Vendor Entry Sheet'!H6 -> 0 | M4: HR
A5: ='Vendor Entry Sheet'!A7 -> 0 | B5: ='Vendor Entry Sheet'!C7 | C5: ='Vendor Entry Sheet'!I7 | D5: ='Vendor Entry Sheet'!J7 | E5: ='Vendor Entry Sheet'!D7 | F5: ='Vendor Entry Sheet'!E7 -> 0 | H5: ='Vendor Entry Sheet'!F7 -> 0 | I5: ='Vendor Entry Sheet'!G7 -> 0 | K5: 1005 | L5: ='Vendor Entry Sheet'!H7 -> 0 | M5: HR
A6: ='Vendor Entry Sheet'!A8 -> 0 | B6: ='Vendor Entry Sheet'!C8 | C6: ='Vendor Entry Sheet'!I8 | D6: ='Vendor Entry Sheet'!J8 | E6: ='Vendor Entry Sheet'!D8 | F6: ='Vendor Entry Sheet'!E8 -> 0 | H6: ='Vendor Entry Sheet'!F8 -> 0 | I6: ='Vendor Entry Sheet'!G8 -> 0 | K6: 1005 | L6: ='Vendor Entry Sheet'!H8 -> 0 | M6: HR
A7: ='Vendor Entry Sheet'!A9 -> 0 | B7: ='Vendor Entry Sheet'!C9 | C7: ='Vendor Entry Sheet'!I9 | D7: ='Vendor Entry Sheet'!J9 | E7: ='Vendor Entry Sheet'!D9 | F7: ='Vendor Entry Sheet'!E9 -> 0 | H7: ='Vendor Entry Sheet'!F9 -> 0 | I7: ='Vendor Entry Sheet'!G9 -> 0 | K7: 1005 | L7: ='Vendor Entry Sheet'!H9 -> 0 | M7: HR
A8: ='Vendor Entry Sheet'!A10 -> 0 | B8: ='Vendor Entry Sheet'!C10 | C8: ='Vendor Entry Sheet'!I10 | D8: ='Vendor Entry Sheet'!J10 | E8: ='Vendor Entry Sheet'!D10 | F8: ='Vendor Entry Sheet'!E10 -> 0 | H8: ='Vendor Entry Sheet'!F10 -> 0 | I8: ='Vendor Entry Sheet'!G10 -> 0 | K8: 1005 | L8: ='Vendor Entry Sheet'!H10 -> 0 | M8: HR
A9: ='Vendor Entry Sheet'!A11 -> 0 | B9: ='Vendor Entry Sheet'!C11 | C9: ='Vendor Entry Sheet'!I11 | D9: ='Vendor Entry Sheet'!J11 | E9: ='Vendor Entry Sheet'!D11 | F9: ='Vendor Entry Sheet'!E11 -> 0 | H9: ='Vendor Entry Sheet'!F11 -> 0 | I9: ='Vendor Entry Sheet'!G11 -> 0 | K9: 1005 | L9: ='Vendor Entry Sheet'!H11 -> 0 | M9: HR
A10: ='Vendor Entry Sheet'!A12 -> 0 | B10: ='Vendor Entry Sheet'!C12 | C10: ='Vendor Entry Sheet'!I12 | D10: ='Vendor Entry Sheet'!J12 | E10: ='Vendor Entry Sheet'!D12 | F10: ='Vendor Entry Sheet'!E12 -> 0 | H10: ='Vendor Entry Sheet'!F12 -> 0 | I10: ='Vendor Entry Sheet'!G12 -> 0 | K10: 1005 | L10: ='Vendor Entry Sheet'!H12 -> 0 | M10: HR
A11: ='Vendor Entry Sheet'!A13 -> 0 | B11: ='Vendor Entry Sheet'!C13 | C11: ='Vendor Entry Sheet'!I13 | D11: ='Vendor Entry Sheet'!J13 | E11: ='Vendor Entry Sheet'!D13 | F11: ='Vendor Entry Sheet'!E13 -> 0 | H11: ='Vendor Entry Sheet'!F13 -> 0 | I11: ='Vendor Entry Sheet'!G13 -> 0 | K11: 1005 | L11: ='Vendor Entry Sheet'!H13 -> 0 | M11: HR
A12: ='Vendor Entry Sheet'!A14 -> 0 | B12: ='Vendor Entry Sheet'!C14 | C12: ='Vendor Entry Sheet'!I14 | D12: ='Vendor Entry Sheet'!J14 | E12: ='Vendor Entry Sheet'!D14 | F12: ='Vendor Entry Sheet'!E14 -> 0 | H12: ='Vendor Entry Sheet'!F14 -> 0 | I12: ='Vendor Entry Sheet'!G14 -> 0 | K12: 1005 | L12: ='Vendor Entry Sheet'!H14 -> 0 | M12: HR
A13: ='Vendor Entry Sheet'!A15 -> 0 | B13: ='Vendor Entry Sheet'!C15 | C13: ='Vendor Entry Sheet'!I15 | D13: ='Vendor Entry Sheet'!J15 | E13: ='Vendor Entry Sheet'!D15 | F13: ='Vendor Entry Sheet'!E15 -> 0 | H13: ='Vendor Entry Sheet'!F15 -> 0 | I13: ='Vendor Entry Sheet'!G15 -> 0 | K13: 1005 | L13: ='Vendor Entry Sheet'!H15 -> 0 | M13: HR
... A339: ='Vendor Entry Sheet'!A341 -> 0 | B339: ='Vendor Entry Sheet'!C341 -> 0 | C339: ='Vendor Entry Sheet'!I341 -> 0 | D339: ='Vendor Entry Sheet'!J341 -> 0 | E339: ='Vendor Entry Sheet'!D341 -> 0 | F339: ='Vendor Entry Sheet'!E341 -> 0 | H339: ='Vendor Entry Sheet'!F341 -> 0 | I339: ='Vendor Entry Sheet'!G341 -> 0 | K339: 1005 | L339: ='Vendor Entry Sheet'!H341 -> 0 | M339: HR

Sheet Names
A1: Company | B1: Name | C1: Sap ID | D1: Role | E1: Service Master | G1: Role | H1: Service Master | J1: Company | K1: Purchase order | L1: Item number
A2: APMS | B2: Rhett Eylward | C2: 90302290 | D2: Supervisor | E2: 3001496 | G2: Crane Operator | H2: 3001496 | J2: SMS Group | K2: 4700023309 | L2: 10
A3: APMS | B3: Jesus Eclarino | C3: 90302290 | D3: Welder | E3: 3001496 | G3: Boom Rigger | H3: 3001496 | J3: TMS | K3: 4700022806 | L3: 10
A4: APMS | B4: Victor Itchon | C4: 90302290 | D4: Welder | E4: 3001496 | G4: Boom Supervisor | H4: 3001496 | J4: Boom | K4: 4700022805 | L4: 10
A5: APMS | B5: Rolando Ola | C5: 90302291 | D5: Supervisor | E5: 3001496 | G5: TMS Supervisor | H5: 3001496 | J5: Minprovise | K5: 4700022724 | L5: 10
A6: APMS | B6: Neil Nopueto | C6: 90302291 | D6: Welder | E6: 3001496 | G6: TMS Boilermaker | H6: 3001496 | J6: APMS | K6: 4700022804 | L6: 10
A7: APMS | B7: Renato Navales | C7: 90302291 | D7: Welder | E7: 3001496 | G7: TMS Fitter | H7: 3001496 | J7: Boom | K7: 4700022805 | L7: 10
A8: Boltprep | B8: Kenneth Gray | C8: 90302294 | D8: Supervisor | E8: 3001496 | G8: GMRS Boilermaker | H8: 3001496 | J8: PO | K8: 4700022803 | L8: 10
A9: Boltprep | B9: Darren Lee | C9: 90302294 | D9: Specialist | E9: 3001496 | G9: GMRS Fitter | H9: 3001496 | J9: CIBS | K9: 4700022734 | L9: 10
A10: Boltprep | B10: Paul Sant | C10: 90302294 | D10: Specialist | E10: 3001496 | G10: GMRS Supervisor | H10: 3001496 | J10: DTH | K10: 4700023527 | L10: 10
A11: Boltprep | B11: Kalen Di Re | C11: 90302295 | D11: Supervisor | E11: 3001496 | G11: Kings Boilermaker | H11: 3001496 | J11: ERM | K11: 4700023066 | L11: 10
A12: Boltprep | B12: Elia Giller | C12: 90302295 | D12: Specialist | E12: 3001496 | G12: Kings Trade Assistant | H12: 3001496 | J12: GEC | K12: 4700023290 | L12: 10
A13: Boltprep | B13: Richard Hittmann | C13: 90302295 | D13: Specialist | E13: 3001496 | G13: Kings Supervisor | H13: 3001496 | J13: GHD | K13: 4700022808 | L13: 10
... A20: Boom | B20: Steven Williams | C20: 90302292 | D20: Crane Op | E20: 3001496 | G20: SMS Supervisor | H20: 3001496 | J20: Prowest | K20: 4700022233 | L20: 10
A21: Boom | B21: Thomas Speck | C21: 90302292 | D21: Crane Op | E21: 3001496 | J21: TMS | K21: 4700022806 | L21: 10
A22: Boom | B22: Sean Doherty | C22: 90302292 | D22: Crane Op | E22: 3001496 | J22: Twomeys | K22: 4700022814 | L22: 10
A23: Boom | B23: David O'Brien | C23: 90302292 | D23: Rigger | E23: 3001496 | J23: Prowest | K23: 4700022233 | L23: 10
A24: Boom | B24: Jamie Hartley | C24: 90302292 | D24: Rigger | E24: 3001496 | J24: Boltprep
A25: Boom | B25: Madeleine Davidson | C25: 90302292 | D25: Rigger | E25: 3001496
A26: Boom | B26: Steve Mackintosh | C26: 90302292 | D26: Rigger | E26: 3001496
A27: Boom | B27: Simon Tanti | C27: 90302292 | D27: Rigger | E27: 3001496
A28: Boom | B28: Richard Chambers | C28: 90302292 | D28: Rigger | E28: 3001496
A29: Boom | B29: Abiel Gebremariam | C29: 90302292 | D29: Rigger | E29: 3001496
A30: Boom | B30: Tommi Harkins | C30: 90302292 | D30: Rigger | E30: 3001496
A31: Boom | B31: Ashton Miller | C31: 90302293 | D31: Supervisor | E31: 3001496
A32: Boom | B32: Tanirau Paki | C32: 90302293 | D32: Crane Op 320T | E32: 3001496
A33: Boom | B33: Gilies Sudrot | C33: 90302293 | D33: Crane Op | E33: 3001496
A34: Boom | B34: Eron Edwards | C34: 90302293 | D34: Crane Op | E34: 3001496
A35: Boom | B35: Egidio De Freitas | C35: 90302293 | D35: Crane Op 70T | E35: 3001496
A36: Boom | B36: Darren Cunningham | C36: 90302293 | D36: Crane Op | E36: 3001496
... A330: Boltprep | B330: Richard Hittmann | C330: 90302835 | D330: Specialist | E330: 3001496

Sheet Approval Box (OFFICE ONLY)

Sheet Work Orders
A1: Work Order | B1: Operation Number | C1: Work Order Header | D1: Op. Short Text | E1: Main Work Center | F1: Company
A2: 16348714 | B2: 0010 | C2: T1 DI001 Cyclone Valves Elec Svce | D2: 4M Disconnect Cyclone Pressure TX | E2: 277SUSS | F2: GEC
A3: 16348714 | B3: 0020 | C3: T1 DI001 Cyclone Valves Elec Svce | D3: 4M Calibrate Cyclone Pressure TX | E3: 277SUSS | F3: GEC
A4: 16348714 | B4: 0030 | C4: T1 DI001 Cyclone Valves Elec Svce | D4: 4M Reconnect Cyclone Pressure TX | E4: 277SUSS | F4: GEC
A5: 16348714 | B5: 0040 | C5: T1 DI001 Cyclone Valves Elec Svce | D5: 4M Align and test valve proxies | E5: 277SUSS | F5: GEC
A6: 16348852 | B6: 0010 | C6: 342PU270 Cons Py Rougher Mech Ovhl | D6: 4M 6E AHF Warman Pump Ops Isolate | E6: 277SUSS | F6: GEC
A7: 16348852 | B7: 0020 | C7: 342PU270 Cons Py Rougher Mech Ovhl | D7: 4M 6E AHF Warman Pump Mech Ovhl | E7: 000SWME | F7: Mader
A8: 16348852 | B8: 0040 | C8: 342PU270 Cons Py Rougher Mech Ovhl | D8: 4M 6E AHF Warman Pump Ovhl 20T CD | E8: 114SWCD | F8: Boom
A9: 16348852 | B9: 0045 | C9: 342PU270 Cons Py Rougher Mech Ovhl | D9: 4M 6E AHF Warman Pump Ovhl 20T CD | E9: 114SURG | F9: Boom
A10: 16348852 | B10: 0050 | C10: 342PU270 Cons Py Rougher Mech Ovhl | D10: 4M 6E AHF Warman Pump Ops Deisolate | E10: 277SUSS | F10: GEC
A11: 16364137 | B11: 0010 | C11: 341FC012 Belts Twisted Mech Repl | D11: 341FC012 Belts Twisted Scaff Handrail | E11: 020SUSC | F11: SMS Group
A12: 16364137 | B12: 0030 | C12: 341FC012 Belts Twisted Mech Repl | D12: 341FC012 Belts Twisted CD Shut | E12: 114SUCD | F12: Boom
... A120: 15885025 | B120: 0210 | C120: T2 ML004 D/Ch End Assembly Mech Repl | D120: ML004 D/Charge 320T CD | E120: 114SUCD | F120: Boom
A121: 15907437 | B121: 0020 | C121: T1 BX014 Box Mech Repl | D121: T1 BX014 Gravity Feed Chute Elec Disconn | E121: 000SWEL
A122: 15907437 | B122: 0030 | C122: T1 BX014 Box Mech Repl | D122: T1 BX014 Gravity Feed Chute Scaff Erect | E122: 020SWSC | F122: SMS Group
A123: 15907437 | B123: 0040 | C123: T1 BX014 Box Mech Repl | D123: Cyclone, Pipe & Steel Structure Remove | E123: 272SUME | F123: TMS
A124: 15907437 | B124: 0050 | C124: T1 BX014 Box Mech Repl | D124: T1 BX014 Gravity Feed Chute Mech Remove | E124: 272SUME | F124: TMS
A125: 15907437 | B125: 0070 | C125: T1 BX014 Box Mech Repl | D125: T1 BX014 Gravity Feed Chute Mech Install | E125: 272SUME | F125: TMS
A126: 15907437 | B126: 0080 | C126: T1 BX014 Box Mech Repl | D126: Cyclone, Pipe & Steel Structure Install | E126: 272SUME | F126: TMS
A127: 15907437 | B127: 0100 | C127: T1 BX014 Box Mech Repl | D127: T1 BX014 Gravity Feed Chute Scaff Down | E127: 020SWSC | F127: SMS Group
A128: 15907437 | B128: 0110 | C128: T1 BX014 Box Mech Repl | D128: T1 BX014 Gravity Feed Chute Elec Install | E128: 277SUSS | F128: GEC
A129: 15911315 | B129: 0020 | C129: 389-DB-201 Distrabution Board Elec Repl | D129: 398-DB-201 Distrabution Board Elec Repl | E129: 000SWEL
A130: 16000789 | B130: 0010 | C130: T1 CT014 Reagent Line Mech Repl | D130: 332CT014 Reagent Line Mech Repl Prep | E130: 272SUME | F130: TMS
A131: 16000789 | B131: 0020 | C131: T1 CT014 Reagent Line Mech Repl | D131: T1 CT014 Reagent Line Old Pipes Remove | E131: 272SUME | F131: TMS
A132: 16000789 | B132: 0030 | C132: T1 CT014 Reagent Line Mech Repl | D132: T1 CT014 Reagent Line Cable Trays Inst | E132: 272SUBM | F132: TMS
A133: 16000789 | B133: 0040 | C133: T1 CT014 Reagent Line Mech Repl | D133: T1 CT014 Reagent Line New Pipes Inst | E133: 272SUME | F133: TMS
A134: 16163867 | B134: 0020 | C134: 333CH200 T2 Stckple Rclm Chute Mech Insp | D134: 2Y 333 Stoc Rclaim Chte Gas Test CSE Pmt | E134: 020SUGT | F134: SMS Group
A135: 16163867 | B135: 0050 | C135: 333CH200 T2 Stckple Rclm Chute Mech Insp | D135: 2Y 333 Stoc Reclaim Chute Insp Sentry | E135: 020SUST | F135: SMS Group
A136: 16250055 | B136: 0025 | C136: T2 BN014 Ball Bunker Lining Mech Repr | D136: T2 BN014 H/baricade Bunker on Lime road | E136: 020SWSC | F136: SMS Group
A137: 16250055 | B137: 0030 | C137: T2 BN014 Ball Bunker Lining Mech Repr | D137: T2 BN014 Ball Bunker Lining Mech Scaff U | E137: 020SWSC | F137: SMS Group
A138: 16250055 | B138: 0040 | C138: T2 BN014 Ball Bunker Lining Mech Repr | D138: T2 BN014 Ball Bunker Lining Mech Repr | E138: 262SURL | F138: Impact
A139: 16250055 | B139: 0050 | C139: T2 BN014 Ball Bunker Lining Mech Repr | D139: T2 BN014 Ball Bunker Lining Mech Sentry | E139: 020SUST | F139: SMS Group
A140: 16250055 | B140: 0070 | C140: T2 BN014 Ball Bunker Lining Mech Repr | D140: T2 BN014 Ball Bunker Lining Mech 25T CD | E140: 114SUCD | F140: Boom
A141: 16250055 | B141: 0080 | C141: T2 BN014 Ball Bunker Lining Mech Repr | D141: T2 BN014 Ball Bunker Lining Mech 25T RG | E141: 114SURG | F141: Boom
... A146: 16304020 | B146: 0030 | C146: Tr2 Cycloconverter Fittings Elec Repl | D146: Tr2 Cycloconverter Fittings Elec Repl | E146: 277SUSS | F146: GEC
A147: 16316599 | B147: 0010 | C147: 351FI001 Cake Ch Deflect Plate Mech Repr | D147: 351FI001 Cake Ch Deflect Plate Mech Repr | E147: 000SWSP
A148: 16320036 | B148: 0010 | C148: T1 332FC002 Feed Pipe Mech Repl | D148: 332FC002 Feed pipe Mech Repl SMS Scaff | E148: 020SWSC | F148: SMS Group
A149: 16320036 | B149: 0020 | C149: T1 332FC002 Feed Pipe Mech Repl | D149: 332FC002 Feed pipe Mech Repl | E149: 272SUME | F149: TMS
A150: 16320036 | B150: 0029 | C150: T1 332FC002 Feed Pipe Mech Repl | D150: 332FC002 Feed pipe Mech Repl 70T RG | E150: 114SURG | F150: Boom
A151: 16320036 | B151: 0030 | C151: T1 332FC002 Feed Pipe Mech Repl | D151: 332FC002 Feed pipe Mech Repl SMS Scaff | E151: 020SWSC | F151: SMS Group
...
